Workbook

Sheet HOW_TO_USE
A2: Shadow AI Operational Maturity Model (SAOMM)
A5: 1. Scope of This Document
A6: This condensed model provides a unified, enterprise‑ready view of AI governance, security, and operational maturity. It consolidates the most authoritative frameworks in the industry into a single, structured assessment model. The document covers:
A7: AI Governance & Responsible AI
A8: AI Strategy, Organization & Resourcing
A9: Data Security & Model Security
A10: LLM Security & Agentic AI Security
A11: Monitoring, Detection & Observability
A12: MLOps, Deployment & Infrastructure Security
A13: MITRE ATLAS Tactics (Condensed)
A14: MITRE ATLAS Mitigations (Condensed)
A15: Each control includes five maturity levels (Level 5 → Level 1), with descriptions and examples to support consistent scoring across teams.
A18: Shadow AI Operational Domains
A19: Domain | C19: Operational Focus
A20: AI Visibility | C20: Discovery of AI SaaS usage and workflow spread
A21: AI Governance | C21: Sanctioned vs unsanctioned AI usage
A22: AI Telemetry | C22: Visibility into prompts, uploads, and AI interactions
A23: AI Identity | C23: OAuth grants, delegated access, AI-linked identities
A24: AI Trust Boundaries | C24: Browser extensions, mediation layers, workflow drift
A25: AI Detection Engineering | C25: Behavioral analytics and AI abuse detection
A26: AI Data Protection | C26: Prompt DLP and sensitive data exposure
A27: AI Incident Response | C27: Investigation and containment of AI-mediated events
A30: Level 1: No Visibility
A31: AI Traffic Ratio unknown
A32: Coverage < 20%
A33: No CASB tagging for AI domains
A34: MTTD undefined
A35: 👉 KPI signature:
A36: AI visibility = 0–20%
A38: Level 2: Domain-Level Detection
A39: AI domains identified (ChatGPT, Claude, Copilot)
A40: AI Traffic Ratio measurable
A41: CASB blocking basic tools
A42: 👉 KPI signature:
... A134: This document synthesizes and reorganizes controls derived from publicly available frameworks including MITRE ATLAS, MITRE AI Maturity Model, OWASP LLM Top 10, OWASP Agentic AI Top 10, NIST AI RMF, and ISO/IEC 42001. The structure, maturity levels, examples, and unified control taxonomy were created by the author.

Sheet Reports
K9: Items | L9: Average score
K10: Governance | L10: =AVERAGE( IFERROR(Governance!F13,0), IFERROR(Governance!F21,0), IFERROR(Governance!F29,0), IFERROR(Governance!F37,0), IFERROR(Governance!F45,0) ) -> 0
K11: Strategy | L11: =AVERAGE( IFERROR(Strategy!F12,0), IFERROR(Strategy!F20,0), IFERROR(Strategy!F28,0) ) -> 0
K12: Organization | L12: =AVERAGE( IFERROR(Organization!F12,0), IFERROR(Organization!F20,0) ) -> 0
K13: Detection | L13: =AVERAGE( IFERROR(Detection!F12,0), IFERROR(Detection!F20,0), IFERROR(Detection!F28,0) ) -> 0
K14: Monitoring | L14: =AVERAGE( IFERROR(Monitoring!F12,0), IFERROR(Monitoring!F20,0), IFERROR(Monitoring!F28,0), IFERROR(Monitoring!F36,0) ) -> 0
K15: Incident Response | L15: =AVERAGE( IFERROR('Incident Response'!F12,0) ) -> 0
K16: ML-Ops | L16: =AVERAGE( IFERROR(MLOPS!F12,0), IFERROR(MLOPS!F20,0) ) -> 0
K17: Deployment | L17: =AVERAGE( IFERROR(Deployment!F12,0) ) -> 0
K18: Infrastructure | L18: =AVERAGE( IFERROR(Infrastructure!F12,0), IFERROR(Infrastructure!F20,0), IFERROR(Infrastructure!F28,0), IFERROR(Infrastructure!F36,0), IFERROR(Infrastructure!F44,0) ) -> 0
K19: Resources | L19: =AVERAGE( IFERROR(Resources!F12,0), IFERROR(Resources!F20,0) ) -> 0
K20: Data Security | L20: =AVERAGE( IFERROR('Data Security'!F12,0), IFERROR('Data Security'!F20,0), IFERROR('Data Security'!F28,0) ) -> 0
K21: Model Security | L21: =AVERAGE( IFERROR('Model Security'!F12,0), IFERROR('Model Security'!F20,0), IFERROR('Model Security'!F28,0), IFERROR('Model Security'!F36,0) ) -> 0
K22: LLM Security | L22: =AVERAGE( IFERROR('LLM Security'!F13,0), IFERROR('LLM Security'!F20,0), IFERROR('LLM Security'!F28,0), IFERROR('LLM Security'!F36,0) ) -> 0
K23: Agent Security | L23: =AVERAGE( IFERROR('Agent Security'!F12,0), IFERROR('Agent Security'!F20,0), IFERROR('Agent Security'!F28,0), IFERROR('Agent Security'!F36,0) ) -> 0
K24: LLM Agent Guardrails | L24: =AVERAGE( IFERROR('LLM-Agent Guardrails'!F12,0) ) -> 0
K25: ATLAS Tactics Coverage | L25: =AVERAGE( IFERROR('ATLAS Tactics Coverage'!F12,0), IFERROR('ATLAS Tactics Coverage'!F20,0), IFERROR('ATLAS Tactics Coverage'!F28,0), IFERROR('ATLAS Tactics Coverage'!F36,0), IFERROR('ATLAS Tactics Coverage'!F44,0), IFERROR('ATLAS Tactics Coverage'!F52,0), IFERROR('ATLAS Tactics Coverage'!F60,0), IFERROR('ATLAS Tactics Coverage'!F68,0), IFERROR('ATLAS Tactics Coverage'!F76,0), IFERROR('ATLAS Tactics Coverage'!F84,0), IFERROR('ATLAS Tactics Coverage'!F92,0), IFERROR('ATLAS Tactics Coverage'!F100,0), IFERROR('ATLAS Tactics Coverage'!F108,0), IFERROR('ATLAS Tactics Coverage'!F116,0) ) -> 0
K26: ATLAS Mitigation Coverage | L26: =AVERAGE( IFERROR('ATLAS Mitigations Coverage'!F12,0), IFERROR('ATLAS Mitigations Coverage'!F20,0), IFERROR('ATLAS Mitigations Coverage'!F28,0), IFERROR('ATLAS Mitigations Coverage'!F36,0), IFERROR('ATLAS Mitigations Coverage'!F44,0), IFERROR('ATLAS Mitigations Coverage'!F52,0), IFERROR('ATLAS Mitigations Coverage'!F60,0), IFERROR('ATLAS Mitigations Coverage'!F68,0), IFERROR('ATLAS Mitigations Coverage'!F76,0), IFERROR('ATLAS Mitigations Coverage'!F84,0), IFERROR('ATLAS Mitigations Coverage'!F92,0), IFERROR('ATLAS Mitigations Coverage'!F100,0), IFERROR('ATLAS Mitigations Coverage'!F108,0), IFERROR('ATLAS Mitigations Coverage'!F116,0), IFERROR('ATLAS Mitigations Coverage'!F124,0), IFERROR('ATLAS Mitigations Coverage'!F132,0), IFERROR('ATLAS Mitigations Coverage'!F140,0), IFERROR('ATLAS Mitigations Coverage'!F148,0), IFERROR('ATLAS Mitigations Coverage'!F156,0), IFERROR('ATLAS Mitigations Coverage'!F164,0), IFERROR('ATLAS Mitigations Coverage'!F172,0), IFERROR('ATLAS Mitigations Coverage'!F180,0), IFERROR('ATLAS Mitigations Coverage'!F188,0), IFERROR('ATLAS Mitigations Coverage'!F196,0) ) -> 0
K28: Total Average Score | L28: =AVERAGE(L10:L26) -> 0

Sheet Governance
A1: Governance
A6: Control Category | B6: Control Name | C6: Maturity Level | D6: Description / Criteria | E6: Example | F6: Score | G6: Comments
A7: Governance | B7: AI Program Governance | C7: Level 5 – Optimized | D7: Governance is automated, continuously monitored, and integrated with enterprise risk systems. | E7: AI governance platform auto‑flags non‑compliant models before deployment.
A8: Governance | B8: AI Program Governance | C8: Level 4 – Managed | D8: Governance processes are standardized, measured, and enforced across all teams. | E8: Mandatory AI review gates in CI/CD.
A9: Governance | B9: AI Program Governance | C9: Level 3 – Defined | D9: Formal governance roles, policies, and processes exist and are documented. | E9: AI steering committee, RACI, policies.
A10: Governance | B10: AI Program Governance | C10: Level 2 – Developing | D10: Some governance exists but is inconsistent or team‑specific. | E10: One team uses a model registry, others don’t.
A11: Governance | B11: AI Program Governance | C11: Level 1 – Initial | D11: No formal governance; ad‑hoc decisions. | E11: No inventory of AI systems.
D13: Total AI Program Governance | F13: =AVERAGE(F7:F11) -> #DIV/0!
A15: Governance | B15: Responsible AI | C15: Level 5 – Optimized | D15: Automated fairness, bias, and transparency checks run continuously. | E15: Bias detection triggers auto‑rollback.
A16: Governance | B16: Responsible AI | C16: Level 4 – Managed | D16: Responsible AI KPIs are monitored and audited. | E16: Quarterly fairness audits.
A17: Governance | B17: Responsible AI | C17: Level 3 – Defined | D17: Responsible AI standards and documentation are formalized. | E17: Model cards, transparency reports.
A18: Governance | B18: Responsible AI | C18: Level 2 – Developing | D18: Basic guidelines exist but are not enforced. | E18: Ethical checklist used by some teams.
A19: Governance | B19: Responsible AI | C19: Level 1 – Initial | D19: No ethical or fairness considerations. | E19: No bias testing.
D21: Total Responsible AI | F21: =AVERAGE(F15:F19) -> #DIV/0!
A23: Governance | B23: AI Risk Management | C23: Level 5 – Optimized | D23: Automated risk scoring and mitigation workflows. | E23: Real‑time risk scoring dashboard.
A24: Governance | B24: AI Risk Management | C24: Level 4 – Managed | D24: Continuous monitoring of AI risks across lifecycle. | E24: Drift alerts tied to risk register.
A25: Governance | B25: AI Risk Management | C25: Level 3 – Defined | D25: Formal AI risk register and assessment process. | E25: Risk scoring templates.
A26: Governance | B26: AI Risk Management | C26: Level 2 – Developing | D26: Ad‑hoc risk reviews. | E26: One‑off risk assessments.
A27: Governance | B27: AI Risk Management | C27: Level 1 – Initial | D27: No AI‑specific risk management. | E27: No tracking of AI risks.
D29: Total AI Risk Management | F29: =AVERAGE(F23:F27) -> #DIV/0!
A31: Governance | B31: AI Policy & Compliance | C31: Level 5 – Optimized | D31: Policies enforced automatically through tooling. | E31: Automated policy enforcement in pipelines.
A32: Governance | B32: AI Policy & Compliance | C32: Level 4 – Managed | D32: Compliance is monitored and audited regularly. | E32: Quarterly compliance audits.
A33: Governance | B33: AI Policy & Compliance | C33: Level 3 – Defined | D33: AI policies exist and are communicated. | E33: AI acceptable‑use policy.
A34: Governance | B34: AI Policy & Compliance | C34: Level 2 – Developing | D34: Draft policies exist but are not enforced. | E34: Draft RAI guidelines.
A35: Governance | B35: AI Policy & Compliance | C35: Level 1 – Initial | D35: No AI policies. | E35: No rules for model usage.
D37: Total AI Policy/Compliance | F37: =AVERAGE(F31:F35) -> #DIV/0!
A39: Governance | B39: AI Inventory & Registry | C39: Level 5 – Optimized | D39: Automated discovery of all AI systems; real‑time updates. | E39: Auto‑scanning cloud for unregistered models.
A40: Governance | B40: AI Inventory & Registry | C40: Level 4 – Managed | D40: Registry is mandatory and enforced. | E40: CI/CD blocks unregistered models.
A41: Governance | B41: AI Inventory & Registry | C41: Level 3 – Defined | D41: Centralized model registry exists. | E41: MLflow, SageMaker, Azure registry.
A42: Governance | B42: AI Inventory & Registry | C42: Level 2 – Developing | D42: Partial inventory exists. | E42: Spreadsheet of models.
A43: Governance | B43: AI Inventory & Registry | C43: Level 1 – Initial | D43: No inventory. | E43: No idea what models exist.
D45: Total AI Inventory/Registry | F45: =AVERAGE(F39:F43) -> #DIV/0!

Sheet Strategy
A1: Strategy
A5: Control Category | B5: Control Name | C5: Maturity Level | D5: Description / Criteria | E5: Example | F5: Score | G5: Comments
A6: Strategy | B6: AI Strategy & Vision | C6: Level 5 – Optimized | D6: AI strategy is continuously refined using real‑time performance, risk, and value metrics. | E6: Strategy auto‑adjusts based on model ROI dashboards.
A7: Strategy | B7: AI Strategy & Vision | C7: Level 4 – Managed | D7: AI strategy is measurable, aligned to business goals, and reviewed regularly. | E7: Annual AI strategy review with KPIs.
A8: Strategy | B8: AI Strategy & Vision | C8: Level 3 – Defined | D8: Documented AI strategy exists and is communicated across the organization. | E8: AI strategy published internally.
A9: Strategy | B9: AI Strategy & Vision | C9: Level 2 – Developing | D9: AI strategy is emerging but incomplete or siloed. | E9: One business unit has an AI roadmap.
A10: Strategy | B10: AI Strategy & Vision | C10: Level 1 – Initial | D10: No AI strategy; ad‑hoc experimentation. | E10: Teams build models without direction.
D12: Total AI Strategy/Vision | F12: =AVERAGE(F6:F10) -> #DIV/0!
A14: Strategy | B14: AI Value Realization | C14: Level 5 – Optimized | D14: Automated measurement of AI value, cost, and impact across the portfolio. | E14: Real‑time ROI dashboards for all models.
A15: Strategy | B15: AI Value Realization | C15: Level 4 – Managed | D15: AI value is measured consistently with standardized KPIs. | E15: Cost savings tracked quarterly.
A16: Strategy | B16: AI Value Realization | C16: Level 3 – Defined | D16: Value measurement frameworks exist. | E16: Business case templates for AI projects.
A17: Strategy | B17: AI Value Realization | C17: Level 2 – Developing | D17: Some value tracking exists but is inconsistent. | E17: One team tracks model performance.
A18: Strategy | B18: AI Value Realization | C18: Level 1 – Initial | D18: No measurement of AI value. | E18: No tracking of AI impact.
D20: Total AI Value Realization | F20: =AVERAGE(F14:F18) -> #DIV/0!
A22: Strategy | B22: AI Portfolio Management | C22: Level 5 – Optimized | D22: Portfolio decisions are automated using risk, performance, and value signals. | E22: Auto‑retirement of low‑value models.
A23: Strategy | B23: AI Portfolio Management | C23: Level 4 – Managed | D23: Portfolio is actively managed with clear prioritization. | E23: Quarterly portfolio reviews.
A24: Strategy | B24: AI Portfolio Management | C24: Level 3 – Defined | D24: AI portfolio is documented and tracked. | E24: Centralized list of all AI initiatives.
A25: Strategy | B25: AI Portfolio Management | C25: Level 2 – Developing | D25: Partial portfolio visibility. | E25: Some projects tracked, others not.
A26: Strategy | B26: AI Portfolio Management | C26: Level 1 – Initial | D26: No portfolio management. | E26: No visibility into AI initiatives.
D28: Total AI Portfolio | F28: =AVERAGE(F22:F26) -> #DIV/0!

Sheet Organization
A1: Organization
A5: Control Category | B5: Control Name | C5: Maturity Level | D5: Description / Criteria | E5: Example | F5: Score | G5: Comments
A6: Organization | B6: AI Organizational Structure | C6: Level 5 – Optimized | D6: AI org structure adapts dynamically to business needs; federated + centralized hybrid. | E6: AI Center of Excellence + embedded teams.
A7: Organization | B7: AI Organizational Structure | C7: Level 4 – Managed | D7: Clear roles, responsibilities, and cross‑functional alignment. | E7: Central AI team with defined charters.
A8: Organization | B8: AI Organizational Structure | C8: Level 3 – Defined | D8: Formal AI org structure exists. | E8: AI lead, MLOps team, governance roles.
A9: Organization | B9: AI Organizational Structure | C9: Level 2 – Developing | D9: Some roles exist but unclear or siloed. | E9: One data scientist per team.
A10: Organization | B10: AI Organizational Structure | C10: Level 1 – Initial | D10: No AI roles or structure. | E10: No dedicated AI staff.
D12: Total AI Organizational | F12: =AVERAGE(F6:F10) -> #DIV/0!
A14: Organization | B14: AI Skills & Workforce | C14: Level 5 – Optimized | D14: Workforce skills are continuously assessed and training is automated/personalized. | E14: AI skill gap analysis auto‑generated.
A15: Organization | B15: AI Skills & Workforce | C15: Level 4 – Managed | D15: Enterprise‑wide AI training programs exist and are measured. | E15: Annual AI upskilling program.
A16: Organization | B16: AI Skills & Workforce | C16: Level 3 – Defined | D16: AI training is available and structured. | E16: AI bootcamps, internal courses.
A17: Organization | B17: AI Skills & Workforce | C17: Level 2 – Developing | D17: Some training exists but is inconsistent. | E17: One team uses Coursera.
A18: Organization | B18: AI Skills & Workforce | C18: Level 1 – Initial | D18: No AI training. | E18: No AI education programs.
D20: Total AI Skills/Workforce | F20: =AVERAGE(F14:F18) -> #DIV/0!

Sheet Detection
A1: Detection
A5: Control Category | B5: Control Name | C5: Maturity Level | D5: Description / Criteria | E5: Example | F5: Score | G5: Comments
A6: Detection | B6: Domain‑Level Detection | C6: Level 5 – Optimized | D6: Autonomous detection of AI threats across domains with risk scoring. | E6: Auto‑flagging anomalous inference patterns.
A7: Detection | B7: Domain‑Level Detection | C7: Level 4 – Managed | D7: ML‑based anomaly detection across AI systems. | E7: Behavioral analytics for model misuse.
A8: Detection | B8: Domain‑Level Detection | C8: Level 3 – Defined | D8: Standardized detection rules and thresholds. | E8: Thresholds for unusual API usage.
A9: Detection | B9: Domain‑Level Detection | C9: Level 2 – Developing | D9: Basic anomaly detection. | E9: Simple volume‑based alerts.
A10: Detection | B10: Domain‑Level Detection | C10: Level 1 – Initial | D10: No detection. | E10: No alerts for abnormal behavior.
D12: Total Domain Lvl Detection | F12: =AVERAGE(F6:F10) -> #DIV/0!
A14: Detection | B14: Prompt‑Level Detection | C14: Level 5 – Optimized | D14: Autonomous detection of malicious prompts using AI‑native Zero Trust. | E14: Auto‑blocking indirect prompt injection.
A15: Detection | B15: Prompt‑Level Detection | C15: Level 4 – Managed | D15: ML‑based detection of harmful prompt patterns. | E15: Prompt anomaly classifier.
A16: Detection | B16: Prompt‑Level Detection | C16: Level 3 – Defined | D16: Standardized prompt validation rules. | E16: Prompt allow/deny lists.
A17: Detection | B17: Prompt‑Level Detection | C17: Level 2 – Developing | D17: Basic keyword‑based detection. | E17: Regex for jailbreak attempts.
A18: Detection | B18: Prompt‑Level Detection | C18: Level 1 – Initial | D18: No prompt detection. | E18: Any prompt accepted.
D20: Total Prompt Lvl Detection | F20: =AVERAGE(F14:F18) -> #DIV/0!
A22: Detection | B22: AI Threat Analytics | C22: Level 5 – Optimized | D22: Autonomous threat correlation across all AI systems. | E22: AI SOC auto‑correlates LLM attacks.
A23: Detection | B23: AI Threat Analytics | C23: Level 4 – Managed | D23: Continuous threat analytics with dashboards. | E23: LLM threat analytics platform.
A24: Detection | B24: AI Threat Analytics | C24: Level 3 – Defined | D24: Documented threat analytics processes. | E24: ATLAS‑aligned threat mapping.
A25: Detection | B25: AI Threat Analytics | C25: Level 2 – Developing | D25: Partial threat analysis. | E25: Manual review of logs.
A26: Detection | B26: AI Threat Analytics | C26: Level 1 – Initial | D26: No threat analytics. | E26: No visibility into AI threats.
D28: Total AI Threat Analytics | F28: =AVERAGE(F22:F26) -> #DIV/0!

Sheet Monitoring
A1: Monitoring
A5: Control Category | B5: Control Name | C5: Maturity Level | D5: Description / Criteria | E5: Example | F5: Score | G5: Comments
A6: Monitoring | B6: AI System Observability | C6: Level 5 – Optimized | D6: Full-stack AI observability with autonomous anomaly detection and automated remediation. | E6: System auto‑rolls back a failing model.
A7: Monitoring | B7: AI System Observability | C7: Level 4 – Managed | D7: Continuous monitoring of inputs, outputs, latency, and performance. | E7: Real‑time dashboards for all models.
A8: Monitoring | B8: AI System Observability | C8: Level 3 – Defined | D8: Standardized observability metrics and logging. | E8: Model latency, accuracy, drift metrics.
A9: Monitoring | B9: AI System Observability | C9: Level 2 – Developing | D9: Partial monitoring; inconsistent metrics. | E9: One team tracks inference latency.
A10: Monitoring | B10: AI System Observability | C10: Level 1 – Initial | D10: No monitoring. | E10: No visibility into model behavior.
D12: Total AI System Obs | F12: =AVERAGE(F6:F10) -> #DIV/0!
A14: Monitoring | B14: Agent Behavior Monitoring | C14: Level 5 – Optimized | D14: Autonomous detection of risky agent behavior with automated containment. | E14: Agent auto‑sandboxed during anomalies.
A15: Monitoring | B15: Agent Behavior Monitoring | C15: Level 4 – Managed | D15: Continuous monitoring of agent actions and tool calls. | E15: Alerts for unusual tool sequences.
A16: Monitoring | B16: Agent Behavior Monitoring | C16: Level 3 – Defined | D16: Standardized behavior logging. | E16: Logs of all agent actions.
A17: Monitoring | B17: Agent Behavior Monitoring | C17: Level 2 – Developing | D17: Partial monitoring. | E17: Logs only some agent actions.
A18: Monitoring | B18: Agent Behavior Monitoring | C18: Level 1 – Initial | D18: No monitoring. | E18: Agent actions invisible.
D20: Total Agent Behavior Monitoring | F20: =AVERAGE(F14:F18) -> #DIV/0!
A22: Monitoring | B22: Model Drift Detection | C22: Level 5 – Optimized | D22: Autonomous drift detection with automated retraining or rollback. | E22: Auto‑rollback when drift exceeds threshold.
A23: Monitoring | B23: Model Drift Detection | C23: Level 4 – Managed | D23: Continuous drift monitoring with alerts. | E23: Drift dashboard with thresholds.
A24: Monitoring | B24: Model Drift Detection | C24: Level 3 – Defined | D24: Documented drift detection processes. | E24: Statistical drift tests.
A25: Monitoring | B25: Model Drift Detection | C25: Level 2 – Developing | D25: Partial drift checks. | E25: Occasional manual drift analysis.
A26: Monitoring | B26: Model Drift Detection | C26: Level 1 – Initial | D26: No drift detection. | E26: Model performance degrades unnoticed.
D28: Total Model Drift Detection | F28: =AVERAGE(F22:F26) -> #DIV/0!
A30: Monitoring | B30: Audit Logging & Traceability | C30: Level 5 – Optimized | D30: Immutable, automated audit logs with full traceability and anomaly detection. | E30: Blockchain‑backed audit logs.
A31: Monitoring | B31: Audit Logging & Traceability | C31: Level 4 – Managed | D31: Continuous audit log monitoring. | E31: Alerts for suspicious log entries.
A32: Monitoring | B32: Audit Logging & Traceability | C32: Level 3 – Defined | D32: Standardized logging across all AI systems. | E32: Input/output logging.
A33: Monitoring | B33: Audit Logging & Traceability | C33: Level 2 – Developing | D33: Partial logging. | E33: Logs only some model interactions.
A34: Monitoring | B34: Audit Logging & Traceability | C34: Level 1 – Initial | D34: No logging. | E34: No record of model activity.
D36: Total Audit Logging Traceability | F36: =AVERAGE(F30:F34) -> #DIV/0!

Sheet Incident Response
A1: Incident Response
A5: Control Category | B5: Control Name | C5: Maturity Level | D5: Description / Criteria | E5: Example | F5: Score | G5: Comments
A6: Incident Response | B6: AI Incident Response | C6: Level 5 – Optimized | D6: Autonomous containment and recovery workflows for AI incidents. | E6: Auto‑quarantine of compromised model.
A7: Incident Response | B7: AI Incident Response | C7: Level 4 – Managed | D7: Continuous monitoring and rehearsed AI‑specific IR plans. | E7: AI red‑team exercises.
A8: Incident Response | B8: AI Incident Response | C8: Level 3 – Defined | D8: Documented AI incident response playbooks. | E8: ATLAS‑aligned IR procedures.
A9: Incident Response | B9: AI Incident Response | C9: Level 2 – Developing | D9: Partial IR processes. | E9: Manual response to AI failures.
A10: Incident Response | B10: AI Incident Response | C10: Level 1 – Initial | D10: No AI‑specific incident response. | E10: No plan for LLM compromise.
D12: Total AI Incident Response | F12: =AVERAGE(F6:F10) -> #DIV/0!

Sheet MLOPS
A1: MLOps
A5: Control Category | B5: Control Name | C5: Maturity Level | D5: Description / Criteria | E5: Example | F5: Score | G5: Comments
A6: MLOps | B6: Model Lifecycle Management | C6: Level 5 – Optimized | D6: Autonomous lifecycle orchestration with automated retraining, rollback, and retirement. | E6: Auto‑retirement of stale models.
A7: MLOps | B7: Model Lifecycle Management | C7: Level 4 – Managed | D7: Continuous lifecycle monitoring with standardized workflows. | E7: CI/CD triggers retraining pipelines.
A8: MLOps | B8: Model Lifecycle Management | C8: Level 3 – Defined | D8: Documented lifecycle processes for development → deployment → monitoring → retirement. | E8: Versioning, approval gates.
A9: MLOps | B9: Model Lifecycle Management | C9: Level 2 – Developing | D9: Partial lifecycle processes. | E9: Some models versioned, others not.
A10: MLOps | B10: Model Lifecycle Management | C10: Level 1 – Initial | D10: No lifecycle management. | E10: Models deployed manually.
D12: Total Model Lifecycle | F12: =AVERAGE(F6:F10) -> #DIV/0!
A14: MLOps | B14: CI/CD for AI | C14: Level 5 – Optimized | D14: Fully automated CI/CD with AI‑specific validation, security checks, and governance gates. | E14: Auto‑block deployment if safety tests fail.
A15: MLOps | B15: CI/CD for AI | C15: Level 4 – Managed | D15: Continuous integration and deployment with automated tests. | E15: Automated model validation suite.
A16: MLOps | B16: CI/CD for AI | C16: Level 3 – Defined | D16: Standardized CI/CD pipelines for AI. | E16: Model registry + deployment pipeline.
A17: MLOps | B17: CI/CD for AI | C17: Level 2 – Developing | D17: Partial automation. | E17: Manual deployment with some scripts.
A18: MLOps | B18: CI/CD for AI | C18: Level 1 – Initial | D18: No CI/CD. | E18: Manual model deployment.
D20: Total CI/CD for AI | F20: =AVERAGE(F14:F18) -> #DIV/0!

Sheet Deployment
A1: Deployment
A5: Control Category | B5: Control Name | C5: Maturity Level | D5: Description / Criteria | E5: Example | F5: Score | G5: Comments
A6: Deployment | B6: Secure Model Deployment | C6: Level 5 – Optimized | D6: Autonomous deployment validation with Zero Trust enforcement. | E6: Auto‑deny deployment of non‑compliant models.
A7: Deployment | B7: Secure Model Deployment | C7: Level 4 – Managed | D7: Deployment security checks enforced consistently. | E7: Security scanning in deployment pipeline.
A8: Deployment | B8: Secure Model Deployment | C8: Level 3 – Defined | D8: Documented deployment security standards. | E8: Deployment checklist.
A9: Deployment | B9: Secure Model Deployment | C9: Level 2 – Developing | D9: Partial deployment controls. | E9: Some models deployed securely.
A10: Deployment | B10: Secure Model Deployment | C10: Level 1 – Initial | D10: No deployment security. | E10: Models deployed without review.
D12: Total Secure Model Deployment | F12: =AVERAGE(F6:F10) -> #DIV/0!

Sheet Infrastructure
A1: Infrastructure
A5: Control Category | B5: Control Name | C5: Maturity Level | D5: Description / Criteria | E5: Example | F5: Score | G5: Comments
A6: Infrastructure | B6: Environment Hardening | C6: Level 5 – Optimized | D6: Autonomous environment hardening with continuous compliance scanning. | E6: Auto‑patching of ML environments.
A7: Infrastructure | B7: Environment Hardening | C7: Level 4 – Managed | D7: Continuous monitoring of environment security. | E7: Vulnerability scanning for ML runtimes.
A8: Infrastructure | B8: Environment Hardening | C8: Level 3 – Defined | D8: Standardized environment hardening procedures. | E8: Hardened containers for inference.
A9: Infrastructure | B9: Environment Hardening | C9: Level 2 – Developing | D9: Partial hardening. | E9: Some secure configs applied.
A10: Infrastructure | B10: Environment Hardening | C10: Level 1 – Initial | D10: No hardening. | E10: Default insecure environments.
D12: Total Environment Hardening | F12: =AVERAGE(F6:F10) -> #DIV/0!
A14: Infrastructure | B14: Sandboxing & Isolation | C14: Level 5 – Optimized | D14: Zero‑Trust execution isolation with autonomous sandboxing. | E14: Auto‑sandboxing during suspicious behavior.
A15: Infrastructure | B15: Sandboxing & Isolation | C15: Level 4 – Managed | D15: Continuous monitoring of sandbox integrity. | E15: Alerts for sandbox escapes.
A16: Infrastructure | B16: Sandboxing & Isolation | C16: Level 3 – Defined | D16: Standardized sandboxing for all models/agents. | E16: Containerized inference.
A17: Infrastructure | B17: Sandboxing & Isolation | C17: Level 2 – Developing | D17: Partial sandboxing. | E17: Some models run in isolated VMs.
A18: Infrastructure | B18: Sandboxing & Isolation | C18: Level 1 – Initial | D18: No sandboxing. | E18: Models run with full system access.
D20: Total Sandboxing/Isolation | F20: =AVERAGE(F14:F18) -> #DIV/0!
A22: Infrastructure | B22: Kill Switch | C22: Level 5 – Optimized | D22: Autonomous kill switch triggered by risk scoring or anomaly detection. | E22: Auto‑shutdown of rogue agent.
A23: Infrastructure | B23: Kill Switch | C23: Level 4 – Managed | D23: Automated kill switch with monitoring. | E23: Kill switch tied to safety metrics.
A24: Infrastructure | B24: Kill Switch | C24: Level 3 – Defined | D24: Documented kill switch procedures. | E24: Manual kill switch in UI.
A25: Infrastructure | B25: Kill Switch | C25: Level 2 – Developing | D25: Partial kill switch capability. | E25: CLI‑based shutdown.
A26: Infrastructure | B26: Kill Switch | C26: Level 1 – Initial | D26: No kill switch. | E26: No way to stop a runaway model.
D28: Total Kill Switch | F28: =AVERAGE(F22:F26) -> #DIV/0!
A30: Infrastructure | B30: AI Zero Trust | C30: Level 5 – Optimized | D30: Full AI‑native Zero Trust with continuous authentication, authorization, and risk scoring. | E30: Dynamic access revocation for models.
A31: Infrastructure | B31: AI Zero Trust | C31: Level 4 – Managed | D31: Zero Trust enforced across AI systems. | E31: Identity‑aware inference endpoints.
A32: Infrastructure | B32: AI Zero Trust | C32: Level 3 – Defined | D32: Zero Trust policies documented. | E32: Access segmentation for AI workloads.
A33: Infrastructure | B33: AI Zero Trust | C33: Level 2 – Developing | D33: Partial Zero Trust controls. | E33: Some identity checks.
A34: Infrastructure | B34: AI Zero Trust | C34: Level 1 – Initial | D34: No Zero Trust. | E34: Flat network, no segmentation.
D36: Total AI Zero Trust | F36: =AVERAGE(F30:F34) -> #DIV/0!
A38: Infrastructure | B38: Dependency & Environment Security | C38: Level 5 – Optimized | D38: Autonomous dependency verification and continuous SBOM monitoring. | E38: Auto‑flagging compromised ML libraries.
A39: Infrastructure | B39: Dependency & Environment Security | C39: Level 4 – Managed | D39: Continuous scanning of ML dependencies. | E39: Automated CVE scanning.
A40: Infrastructure | B40: Dependency & Environment Security | C40: Level 3 – Defined | D40: SBOM required for all models. | E40: MLflow + SBOM integration.
A41: Infrastructure | B41: Dependency & Environment Security | C41: Level 2 – Developing | D41: Partial dependency tracking. | E41: Some libraries tracked manually.
A42: Infrastructure | B42: Dependency & Environment Security | C42: Level 1 – Initial | D42: No supply chain controls. | E42: Unknown ML dependencies.
D44: Total Dependency/Environment Security | F44: =AVERAGE(F38:F42) -> #DIV/0!

Sheet Resources
A1: Resources
A5: Control Category | B5: Control Name | C5: Maturity Level | D5: Description / Criteria | E5: Example | F5: Score | G5: Comments
A6: Resources | B6: AI Budgeting & Funding | C6: Level 5 – Optimized | D6: Funding is dynamic, value‑based, and automated. | E6: Funding shifts based on model ROI.
A7: Resources | B7: AI Budgeting & Funding | C7: Level 4 – Managed | D7: AI budget is planned, tracked, and aligned to strategy. | E7: Annual AI budget cycle.
A8: Resources | B8: AI Budgeting & Funding | C8: Level 3 – Defined | D8: AI funding model exists. | E8: Dedicated AI budget line.
A9: Resources | B9: AI Budgeting & Funding | C9: Level 2 – Developing | D9: Some funding exists but is inconsistent. | E9: One team gets AI budget.
A10: Resources | B10: AI Budgeting & Funding | C10: Level 1 – Initial | D10: No dedicated AI funding. | E10: AI projects rely on leftover budgets.
D12: Total AI Budgeting/Funding | F12: =AVERAGE(F6:F10) -> #DIV/0!
A14: Resources | B14: AI Tools & Platforms | C14: Level 5 – Optimized | D14: Tooling is automated, scalable, and self‑service across the org. | E14: Auto‑provisioned GPU clusters.
A15: Resources | B15: AI Tools & Platforms | C15: Level 4 – Managed | D15: Standardized AI platforms are used across teams. | E15: Enterprise MLOps platform.
A16: Resources | B16: AI Tools & Platforms | C16: Level 3 – Defined | D16: Tools and platforms are documented and supported. | E16: Approved AI tool catalog.
A17: Resources | B17: AI Tools & Platforms | C17: Level 2 – Developing | D17: Tools exist but are inconsistent across teams. | E17: One team uses Databricks, others don’t.
A18: Resources | B18: AI Tools & Platforms | C18: Level 1 – Initial | D18: No AI tooling strategy. | E18: Teams use ad‑hoc tools.
D20: Total AI Tools/Platforms | F20: =AVERAGE(F14:F18) -> #DIV/0!

Sheet Data Security
A1: Data Security
A5: Control Category | B5: Control Name | C5: Maturity Level | D5: Description / Criteria | E5: Example | F5: Score | G5: Comments
A6: Data Security | B6: Data Governance & Quality | C6: Level 5 – Optimized | D6: Automated data validation, lineage tracking, and quality scoring across all pipelines. | E6: Real‑time data quality scoring with auto‑remediation.
A7: Data Security | B7: Data Governance & Quality | C7: Level 4 – Managed | D7: Standardized data governance enforced across teams. | E7: Mandatory data lineage tracking.
A8: Data Security | B8: Data Governance & Quality | C8: Level 3 – Defined | D8: Documented data governance processes exist. | E8: Data dictionaries, lineage diagrams.
A9: Data Security | B9: Data Governance & Quality | C9: Level 2 – Developing | D9: Partial governance; inconsistent quality checks. | E9: Some datasets validated manually.
A10: Data Security | B10: Data Governance & Quality | C10: Level 1 – Initial | D10: No data governance or quality controls. | E10: No validation of training data.
D12: Total Data Governance/Quality | F12: =AVERAGE(F6:F10) -> #DIV/0!
A14: Data Security | B14: Data Poisoning Defense | C14: Level 5 – Optimized | D14: Autonomous detection and mitigation of poisoning attempts across all data sources. | E14: Auto‑flagging anomalous training samples.
A15: Data Security | B15: Data Poisoning Defense | C15: Level 4 – Managed | D15: Continuous monitoring for poisoning indicators. | E15: Drift detection tied to alerts.
A16: Data Security | B16: Data Poisoning Defense | C16: Level 3 – Defined | D16: Automated validation and sanitization pipelines. | E16: Outlier filtering before training.
A17: Data Security | B17: Data Poisoning Defense | C17: Level 2 – Developing | D17: Manual dataset reviews. | E17: Manual spot‑checks for anomalies.
A18: Data Security | B18: Data Poisoning Defense | C18: Level 1 – Initial | D18: No poisoning defenses. | E18: Any data can enter training.
D20: Total Data Poisoning Defense | F20: =AVERAGE(F14:F18) -> #DIV/0!
A22: Data Security | B22: Sensitive Data Protection | C22: Level 5 – Optimized | D22: Automated PII detection, redaction, and encryption across all AI workflows. | E22: Auto‑redaction of PII in prompts.
A23: Data Security | B23: Sensitive Data Protection | C23: Level 4 – Managed | D23: Consistent enforcement of data protection policies. | E23: PII scanning in pipelines.
A24: Data Security | B24: Sensitive Data Protection | C24: Level 3 – Defined | D24: Documented data protection standards. | E24: PII classification guidelines.
A25: Data Security | B25: Sensitive Data Protection | C25: Level 2 – Developing | D25: Partial PII handling controls. | E25: Manual redaction.
A26: Data Security | B26: Sensitive Data Protection | C26: Level 1 – Initial | D26: No PII protection. | E26: Sensitive data appears in training sets.
D28: Total Sensitive Data Protection | F28: #DIV/0!

Sheet Model Security
A1: Model Security
A5: Control Category | B5: Control Name | C5: Maturity Level | D5: Description / Criteria | E5: Example | F5: Score | G5: Comments
A6: Model Security | B6: Model Hardening | C6: Level 5 – Optimized | D6: Automated adversarial training and continuous robustness testing. | E6: Auto‑generated adversarial examples.
A7: Model Security | B7: Model Hardening | C7: Level 4 – Managed | D7: Regular adversarial testing and model robustness reviews. | E7: Quarterly red‑team testing.
A8: Model Security | B8: Model Hardening | C8: Level 3 – Defined | D8: Documented hardening techniques applied. | E8: Gradient masking, noise injection.
A9: Model Security | B9: Model Hardening | C9: Level 2 – Developing | D9: Some hardening applied inconsistently. | E9: One model uses adversarial training.
A10: Model Security | B10: Model Hardening | C10: Level 1 – Initial | D10: No model hardening. | E10: Models vulnerable to simple attacks.
D12: Total Model Hardening | F12: =AVERAGE(F6:F10) -> #DIV/0!
A14: Model Security | B14: Model Theft Defense | C14: Level 5 – Optimized | D14: Zero‑Trust inference isolation with automated extraction detection. | E14: Auto‑blocking suspicious query patterns.
A15: Model Security | B15: Model Theft Defense | C15: Level 4 – Managed | D15: Continuous monitoring for extraction attempts. | E15: Rate‑limit anomalies trigger alerts.
A16: Model Security | B16: Model Theft Defense | C16: Level 3 – Defined | D16: Standardized protections implemented. | E16: Query rate limiting, watermarking.
A17: Model Security | B17: Model Theft Defense | C17: Level 2 – Developing | D17: Basic protections exist. | E17: Simple throttling.
A18: Model Security | B18: Model Theft Defense | C18: Level 1 – Initial | D18: No protections. | E18: Unlimited inference queries.
D20: Total Model Theft Defense | F20: =AVERAGE(F14:F18) -> #DIV/0!
A22: Model Security | B22: Model Supply Chain Security | C22: Level 5 – Optimized | D22: Autonomous dependency verification and continuous SBOM monitoring. | E22: Auto‑flagging compromised ML libraries.
A23: Model Security | B23: Model Supply Chain Security | C23: Level 4 – Managed | D23: Continuous scanning of ML dependencies. | E23: Automated CVE scanning.
A24: Model Security | B24: Model Supply Chain Security | C24: Level 3 – Defined | D24: SBOM required for all models. | E24: MLflow + SBOM integration.
A25: Model Security | B25: Model Supply Chain Security | C25: Level 2 – Developing | D25: Partial dependency tracking. | E25: Some libraries tracked manually.
A26: Model Security | B26: Model Supply Chain Security | C26: Level 1 – Initial | D26: No supply chain controls. | E26: Unknown ML dependencies.
D28: Total Model Supply Chain Security | F28: =AVERAGE(F22:F26) -> #DIV/0!
A30: Model Security | B30: Model Access Control | C30: Level 5 – Optimized | D30: Zero‑Trust access with continuous authentication and risk scoring. | E30: Dynamic access revocation.
A31: Model Security | B31: Model Access Control | C31: Level 4 – Managed | D31: Role‑based access enforced across all models. | E31: RBAC for inference endpoints.
A32: Model Security | B32: Model Access Control | C32: Level 3 – Defined | D32: Access control policies documented. | E32: Access matrix for models.
A33: Model Security | B33: Model Access Control | C33: Level 2 – Developing | D33: Some access controls exist. | E33: API keys per team.
A34: Model Security | B34: Model Access Control | C34: Level 1 – Initial | D34: No access control. | E34: Anyone can query models.
D36: Total Model Access Control | F36: =AVERAGE(F30:F34) -> #DIV/0!

Sheet LLM Security
A1: LLM Security
A5: Control Category | B5: Control Name | C5: Maturity Level | D5: Description / Criteria | E5: Example | F5: Score | G5: Comments
A6: LLM Security | B6: Prompt Injection Defense | C6: Level 5 – Optimized | D6: Autonomous detection and blocking of direct/indirect prompt injection using AI‑native Zero Trust. | E6: System auto‑isolates malicious prompt patterns.
A7: LLM Security | B7: Prompt Injection Defense | C7: Level 4 – Managed | D7: ML‑based detection of injection attempts with automated alerts. | E7: Behavioral prompt anomaly detection.
A8: LLM Security | B8: Prompt Injection Defense | C8: Level 3 – Defined | D8: Standardized prompt validation and sanitization pipeline. | E8: Context filtering, allow/deny lists.
A9: LLM Security | B9: Prompt Injection Defense | C9: Level 2 – Developing | D9: Basic keyword‑based filtering. | E9: Regex for “ignore previous instructions”.
A10: LLM Security | B10: Prompt Injection Defense | C10: Level 1 – Initial | D10: No protections. | E10: Model accepts any prompt.
D12: Total Prompt Injection Defense | F12: =AVERAGE(F6:F10) -> #DIV/0!
A14: LLM Security | B14: Output Hardening | C14: Level 5 – Optimized | D14: Autonomous output filtering, redaction, and safety scoring. | E14: Auto‑blocking harmful outputs.
A15: LLM Security | B15: Output Hardening | C15: Level 4 – Managed | D15: ML‑based output moderation with continuous tuning. | E15: Toxicity classifier + human review.
A16: LLM Security | B16: Output Hardening | C16: Level 3 – Defined | D16: Standardized output validation rules. | E16: Safety filters for PII, harmful content.
A17: LLM Security | B17: Output Hardening | C17: Level 2 – Developing | D17: Basic output checks. | E17: Simple profanity filter.
A18: LLM Security | B18: Output Hardening | C18: Level 1 – Initial | D18: No output controls. | E18: Model outputs unsafe content.
D20: Total Output Hardening | F20: =AVERAGE(F14:F18) -> #DIV/0!
A22: LLM Security | B22: Hallucination Mitigation | C22: Level 5 – Optimized | D22: Automated fact‑checking and retrieval‑augmented validation. | E22: RAG pipeline auto‑corrects hallucinations.
A23: LLM Security | B23: Hallucination Mitigation | C23: Level 4 – Managed | D23: Continuous monitoring of hallucination rates. | E23: Hallucination KPI dashboard.
A24: LLM Security | B24: Hallucination Mitigation | C24: Level 3 – Defined | D24: Documented hallucination controls. | E24: Retrieval‑augmented generation (RAG).
A25: LLM Security | B25: Hallucination Mitigation | C25: Level 2 – Developing | D25: Some mitigation techniques used inconsistently. | E25: Prompt engineering for accuracy.
A26: LLM Security | B26: Hallucination Mitigation | C26: Level 1 – Initial | D26: No hallucination controls. | E26: Model fabricates facts.
D28: Total Hallucination Mitigation | F28: =AVERAGE(F22:F26) -> #DIV/0!
A30: LLM Security | B30: Data Leakage Prevention | C30: Level 5 – Optimized | D30: Autonomous detection and blocking of sensitive data in prompts and outputs. | E30: Auto‑redaction of PII in real time.
A31: LLM Security | B31: Data Leakage Prevention | C31: Level 4 – Managed | D31: Continuous monitoring for leakage patterns. | E31: Alerts for sensitive data exposure.
A32: LLM Security | B32: Data Leakage Prevention | C32: Level 3 – Defined | D32: Standardized DLP rules for LLMs. | E32: PII scanning in prompts.
A33: LLM Security | B33: Data Leakage Prevention | C33: Level 2 – Developing | D33: Partial DLP controls. | E33: Manual redaction.
A34: LLM Security | B34: Data Leakage Prevention | C34: Level 1 – Initial | D34: No DLP controls. | E34: Model leaks internal data.
D36: Total Data Leakage Prevention | F36: =AVERAGE(F30:F34) -> #DIV/0!

Sheet Agent Security
A1: Agent Security
A5: Control Category | B5: Control Name | C5: Maturity Level | D5: Description / Criteria | E5: Example | F5: Score | G5: Comments
A6: Agent Security | B6: Tool‑Use Security | C6: Level 5 – Optimized | D6: Autonomous risk scoring of tool calls with dynamic privilege adjustment. | E6: Agent loses access if behavior becomes risky.
A7: Agent Security | B7: Tool‑Use Security | C7: Level 4 – Managed | D7: Continuous monitoring of tool usage. | E7: Alerts for unusual tool invocation patterns.
A8: Agent Security | B8: Tool‑Use Security | C8: Level 3 – Defined | D8: Role‑based tool access and guardrails. | E8: Agent can only call approved tools.
A9: Agent Security | B9: Tool‑Use Security | C9: Level 2 – Developing | D9: Basic tool restrictions. | E9: Hardcoded allow‑list.
A10: Agent Security | B10: Tool‑Use Security | C10: Level 1 – Initial | D10: No tool‑use controls. | E10: Agent can execute any tool.
D12: Total Tool Use Security | F12: =AVERAGE(F6:F10) -> #DIV/0!
A14: Agent Security | B14: Agent Memory Security | C14: Level 5 – Optimized | D14: Zero‑Trust memory segmentation with autonomous poisoning detection. | E14: Memory auto‑cleans malicious entries.
A15: Agent Security | B15: Agent Memory Security | C15: Level 4 – Managed | D15: Continuous monitoring of memory integrity. | E15: Alerts for suspicious memory updates.
A16: Agent Security | B16: Agent Memory Security | C16: Level 3 – Defined | D16: Standardized memory sanitization pipeline. | E16: Validation before writing to memory.
A17: Agent Security | B17: Agent Memory Security | C17: Level 2 – Developing | D17: Partial memory controls. | E17: Manual memory review.
A18: Agent Security | B18: Agent Memory Security | C18: Level 1 – Initial | D18: No memory protections. | E18: Agent stores untrusted data.
D20: Total Agent Memory Security | F20: =AVERAGE(F14:F18) -> #DIV/0!
A22: Agent Security | B22: Agent Autonomy Controls | C22: Level 5 – Optimized | D22: Autonomous risk‑based throttling of agent autonomy. | E22: Agent autonomy reduced during anomalies.
A23: Agent Security | B23: Agent Autonomy Controls | C23: Level 4 – Managed | D23: Autonomy levels monitored and governed. | E23: Autonomy KPI dashboard.
A24: Agent Security | B24: Agent Autonomy Controls | C24: Level 3 – Defined | D24: Documented autonomy levels and policies. | E24: Tiered autonomy model.
A25: Agent Security | B25: Agent Autonomy Controls | C25: Level 2 – Developing | D25: Some autonomy restrictions. | E25: Hardcoded limits.
A26: Agent Security | B26: Agent Autonomy Controls | C26: Level 1 – Initial | D26: No autonomy controls. | E26: Agent can act freely.
D28: Total Agent Autonomy Controls | F28: =AVERAGE(F22:F26) -> #DIV/0!
A30: Agent Security | B30: Agent Sandbox & Isolation | C30: Level 5 – Optimized | D30: Zero‑Trust execution environment with autonomous isolation. | E30: Agent auto‑sandboxed during risky behavior.
A31: Agent Security | B31: Agent Sandbox & Isolation | C31: Level 4 – Managed | D31: Continuous monitoring of agent execution. | E31: Alerts for sandbox escapes.
A32: Agent Security | B32: Agent Sandbox & Isolation | C32: Level 3 – Defined | D32: Standardized sandboxing for all agents. | E32: Containerized agent execution.
A33: Agent Security | B33: Agent Sandbox & Isolation | C33: Level 2 – Developing | D33: Partial sandboxing. | E33: Some agents run in isolated VMs.
A34: Agent Security | B34: Agent Sandbox & Isolation | C34: Level 1 – Initial | D34: No sandboxing. | E34: Agents run with full system access.
D36: Total Agent Sandbox Isolation | F36: =AVERAGE(F30:F34) -> #DIV/0!

Sheet LLM-Agent Guardrails
A1: LLM/Agent Safety
A5: Control Category | B5: Control Name | C5: Maturity Level | D5: Description / Criteria | E5: Example | F5: Score | G5: Comments
A6: LLM/Agent Safety | B6: Safety Guardrails | C6: Level 5 – Optimized | D6: Autonomous guardrail enforcement with dynamic policy adaptation. | E6: Guardrails adjust based on context.
A7: LLM/Agent Safety | B7: Safety Guardrails | C7: Level 4 – Managed | D7: Continuous monitoring of guardrail effectiveness. | E7: Safety KPI dashboard.
A8: LLM/Agent Safety | B8: Safety Guardrails | C8: Level 3 – Defined | D8: Standardized guardrails across all LLMs/agents. | E8: Safety policies in prompt templates.
A9: LLM/Agent Safety | B9: Safety Guardrails | C9: Level 2 – Developing | D9: Partial guardrails. | E9: Hardcoded safety prompts.
A10: LLM/Agent Safety | B10: Safety Guardrails | C10: Level 1 – Initial | D10: No guardrails. | E10: Model outputs unsafe actions.
D12: Total Safety Guardrails | F12: =AVERAGE(F6:F10) -> #DIV/0!

Sheet ATLAS Tactics Coverage
A1: ATLAS Tactic Coverage
A5: Control Category | B5: Control Name | C5: Maturity Level | D5: Description / Criteria | E5: Example | F5: Score | G5: Comments
A6: ATLAS Tactic | B6: Reconnaissance Defense | C6: Level 5 – Optimized | D6: Autonomous detection of reconnaissance patterns with automated blocking. | E6: Auto‑blocking repeated probing queries.
A7: ATLAS Tactic | B7: Reconnaissance Defense | C7: Level 4 – Managed | D7: Continuous monitoring for reconnaissance attempts. | E7: Alerts for unusual metadata requests.
A8: ATLAS Tactic | B8: Reconnaissance Defense | C8: Level 3 – Defined | D8: Documented defenses against reconnaissance. | E8: Rate limits, metadata suppression.
A9: ATLAS Tactic | B9: Reconnaissance Defense | C9: Level 2 – Developing | D9: Partial protections. | E9: Basic throttling.
A10: ATLAS Tactic | B10: Reconnaissance Defense | C10: Level 1 – Initial | D10: No protections. | E10: System reveals model details freely.
D12: Total Reconnaissance Defense | F12: =AVERAGE(F6:F10) -> #DIV/0!
A14: ATLAS Tactic | B14: Initial Access Defense | C14: Level 5 – Optimized | D14: Zero‑Trust access with continuous authentication and risk scoring. | E14: Dynamic access revocation.
A15: ATLAS Tactic | B15: Initial Access Defense | C15: Level 4 – Managed | D15: Strong authentication and monitoring. | E15: MFA + behavioral analytics.
A16: ATLAS Tactic | B16: Initial Access Defense | C16: Level 3 – Defined | D16: Documented access control policies. | E16: RBAC for AI endpoints.
A17: ATLAS Tactic | B17: Initial Access Defense | C17: Level 2 – Developing | D17: Basic access controls. | E17: API keys.
A18: ATLAS Tactic | B18: Initial Access Defense | C18: Level 1 – Initial | D18: No access controls. | E18: Open inference endpoints.
D20: Total Initial Access Defense | F20: =AVERAGE(F14:F18) -> #DIV/0!
A22: ATLAS Tactic | B22: Execution Defense | C22: Level 5 – Optimized | D22: Autonomous detection and containment of malicious execution. | E22: Auto‑sandboxing malicious actions.
A23: ATLAS Tactic | B23: Execution Defense | C23: Level 4 – Managed | D23: Continuous monitoring of execution behavior. | E23: Alerts for abnormal inference patterns.
A24: ATLAS Tactic | B24: Execution Defense | C24: Level 3 – Defined | D24: Standardized execution controls. | E24: Execution allow/deny lists.
A25: ATLAS Tactic | B25: Execution Defense | C25: Level 2 – Developing | D25: Partial execution controls. | E25: Some commands blocked.
A26: ATLAS Tactic | B26: Execution Defense | C26: Level 1 – Initial | D26: No execution controls. | E26: Any action allowed.
D28: Total Execution Defense | F28: =AVERAGE(F22:F26) -> #DIV/0!
A30: ATLAS Tactic | B30: Persistence Defense | C30: Level 5 – Optimized | D30: Autonomous detection of persistent footholds. | E30: Auto‑revocation of suspicious tokens.
A31: ATLAS Tactic | B31: Persistence Defense | C31: Level 4 – Managed | D31: Continuous monitoring for persistence indicators. | E31: Alerts for long‑lived sessions.
A32: ATLAS Tactic | B32: Persistence Defense | C32: Level 3 – Defined | D32: Documented persistence defenses. | E32: Token rotation policies.
A33: ATLAS Tactic | B33: Persistence Defense | C33: Level 2 – Developing | D33: Partial persistence controls. | E33: Manual token cleanup.
A34: ATLAS Tactic | B34: Persistence Defense | C34: Level 1 – Initial | D34: No persistence controls. | E34: Tokens never expire.
D36: Total Persistence Defense | F36: =AVERAGE(F30:F34) -> #DIV/0!
A38: ATLAS Tactic | B38: Privilege Escalation Defense | C38: Level 5 – Optimized | D38: Autonomous privilege reduction based on risk. | E38: Auto‑downgrading suspicious accounts.
A39: ATLAS Tactic | B39: Privilege Escalation Defense | C39: Level 4 – Managed | D39: Continuous monitoring of privilege changes. | E39: Alerts for privilege anomalies.
A40: ATLAS Tactic | B40: Privilege Escalation Defense | C40: Level 3 – Defined | D40: Standardized privilege policies. | E40: RBAC + least privilege.
A41: ATLAS Tactic | B41: Privilege Escalation Defense | C41: Level 2 – Developing | D41: Partial privilege controls. | E41: Manual privilege reviews.
A42: ATLAS Tactic | B42: Privilege Escalation Defense | C42: Level 1 – Initial | D42: No privilege controls. | E42: All users have admin access.
D44: Total Privilege Escalation Defense | F44: =AVERAGE(F38:F42) -> #DIV/0!
A46: ATLAS Tactic | B46: Defense Evasion | C46: Level 5 – Optimized | D46: Autonomous detection of evasion patterns. | E46: Auto‑flagging obfuscated prompts.
A47: ATLAS Tactic | B47: Defense Evasion | C47: Level 4 – Managed | D47: Continuous monitoring for evasion attempts. | E47: Alerts for bypass attempts.
A48: ATLAS Tactic | B48: Defense Evasion | C48: Level 3 – Defined | D48: Documented evasion defenses. | E48: Prompt normalization.
A49: ATLAS Tactic | B49: Defense Evasion | C49: Level 2 – Developing | D49: Partial defenses. | E49: Basic pattern checks.
A50: ATLAS Tactic | B50: Defense Evasion | C50: Level 1 – Initial | D50: No defenses. | E50: Evasion attempts succeed.
D52: Total Defense Evasion | F52: =AVERAGE(F46:F50) -> #DIV/0!
A54: ATLAS Tactic | B54: Credential Access | C54: Level 5 – Optimized | D54: Autonomous detection of credential theft attempts. | E54: Auto‑revocation of compromised keys.
A55: ATLAS Tactic | B55: Credential Access | C55: Level 4 – Managed | D55: Continuous monitoring of credential usage. | E55: Alerts for unusual API key use.
...

Sheet ATLAS Mitigations Coverage
A1: ATLAS Mitigation
A5: Control Category | B5: Control Name | C5: Maturity Level | D5: Description / Criteria | E5: Example | F5: Score | G5: Comments
A6: ATLAS Mitigation | B6: Adversarial Training | C6: Level 5 – Optimized | D6: Continuous adversarial retraining with automated generation of adversarial examples. | E6: Auto‑generated adversarial samples.
A7: ATLAS Mitigation | B7: Adversarial Training | C7: Level 4 – Managed | D7: Regular adversarial testing and retraining. | E7: Quarterly adversarial robustness tests.
A8: ATLAS Mitigation | B8: Adversarial Training | C8: Level 3 – Defined | D8: Documented adversarial training procedures. | E8: FGSM, PGD training.
A9: ATLAS Mitigation | B9: Adversarial Training | C9: Level 2 – Developing | D9: Partial adversarial training. | E9: One model hardened.
A10: ATLAS Mitigation | B10: Adversarial Training | C10: Level 1 – Initial | D10: No adversarial training. | E10: Model vulnerable to simple attacks.
D12: Total Adversarial Training | F12: =AVERAGE(F6:F10) -> #DIV/0!
A14: ATLAS Mitigation | B14: Input Validation | C14: Level 5 – Optimized | D14: Autonomous input sanitization with AI‑native Zero Trust. | E14: Auto‑blocking malicious prompts.
A15: ATLAS Mitigation | B15: Input Validation | C15: Level 4 – Managed | D15: ML‑based input anomaly detection. | E15: Behavioral input classifier.
A16: ATLAS Mitigation | B16: Input Validation | C16: Level 3 – Defined | D16: Standardized input validation rules. | E16: Allow/deny lists.
A17: ATLAS Mitigation | B17: Input Validation | C17: Level 2 – Developing | D17: Basic validation. | E17: Regex filtering.
A18: ATLAS Mitigation | B18: Input Validation | C18: Level 1 – Initial | D18: No validation. | E18: Any input accepted.
D20: Total Input Validation | F20: =AVERAGE(F14:F18) -> #DIV/0!
A22: ATLAS Mitigation | B22: Data Sanitization | C22: Level 5 – Optimized | D22: Fully automated sanitization with anomaly detection and poisoning defense. | E22: Auto‑flagging poisoned samples.
A23: ATLAS Mitigation | B23: Data Sanitization | C23: Level 4 – Managed | D23: Continuous monitoring of data quality. | E23: Drift + anomaly alerts.
A24: ATLAS Mitigation | B24: Data Sanitization | C24: Level 3 – Defined | D24: Standardized sanitization pipeline. | E24: Outlier removal, deduplication.
A25: ATLAS Mitigation | B25: Data Sanitization | C25: Level 2 – Developing | D25: Partial sanitization. | E25: Manual dataset review.
A26: ATLAS Mitigation | B26: Data Sanitization | C26: Level 1 – Initial | D26: No sanitization. | E26: Raw data used directly.
D28: Total Data Sanitization | F28: =AVERAGE(F22:F26) -> #DIV/0!
A30: ATLAS Mitigation | B30: Data Label Verification | C30: Level 5 – Optimized | D30: Automated label validation using ML + human‑in‑the‑loop escalation. | E30: Auto‑flag mislabeled samples.
A31: ATLAS Mitigation | B31: Data Label Verification | C31: Level 4 – Managed | D31: Continuous monitoring of label integrity. | E31: Label drift alerts.
A32: ATLAS Mitigation | B32: Data Label Verification | C32: Level 3 – Defined | D32: Standardized label QA processes. | E32: Dual‑annotator workflow.
A33: ATLAS Mitigation | B33: Data Label Verification | C33: Level 2 – Developing | D33: Partial label checks. | E33: Spot‑checking labels.
A34: ATLAS Mitigation | B34: Data Label Verification | C34: Level 1 – Initial | D34: No label verification. | E34: Labels taken at face value.
D36: Total Data Label Verification | F36: =AVERAGE(F30:F34) -> #DIV/0!
A38: ATLAS Mitigation | B38: Data Provenance Tracking | C38: Level 5 – Optimized | D38: Automated provenance tracking with immutable lineage. | E38: Blockchain‑backed lineage.
A39: ATLAS Mitigation | B39: Data Provenance Tracking | C39: Level 4 – Managed | D39: Continuous monitoring of data sources. | E39: Alerts for untrusted sources.
A40: ATLAS Mitigation | B40: Data Provenance Tracking | C40: Level 3 – Defined | D40: Documented provenance requirements. | E40: Source metadata stored in registry.
A41: ATLAS Mitigation | B41: Data Provenance Tracking | C41: Level 2 – Developing | D41: Partial provenance tracking. | E41: Some datasets tagged manually.
A42: ATLAS Mitigation | B42: Data Provenance Tracking | C42: Level 1 – Initial | D42: No provenance tracking. | E42: Unknown data origins.
D44: Total Data Provenance Tracking | F44: =AVERAGE(F38:F42) -> #DIV/0!
A46: ATLAS Mitigation | B46: Secure Data Storage | C46: Level 5 – Optimized | D46: Autonomous encryption, key rotation, and access scoring. | E46: Auto‑revoking risky access.
A47: ATLAS Mitigation | B47: Secure Data Storage | C47: Level 4 – Managed | D47: Continuous monitoring of data access. | E47: Alerts for unusual reads.
A48: ATLAS Mitigation | B48: Secure Data Storage | C48: Level 3 – Defined | D48: Standardized encryption and access policies. | E48: KMS + RBAC.
A49: ATLAS Mitigation | B49: Secure Data Storage | C49: Level 2 – Developing | D49: Partial encryption. | E49: Some datasets encrypted.
A50: ATLAS Mitigation | B50: Secure Data Storage | C50: Level 1 – Initial | D50: No secure storage. | E50: Plaintext training data.
D52: Total AI Threat Analytics | F52: =AVERAGE(F46:F50) -> #DIV/0!
A54: ATLAS Mitigation | B54: Training Pipeline Integrity | C54: Level 5 – Optimized | D54: Autonomous integrity verification with rollback. | E54: Auto‑rollback on pipeline tampering.
A55: ATLAS Mitigation | B55: Training Pipeline Integrity | C55: Level 4 – Managed | D55: Continuous monitoring of pipeline integrity. | E55: Alerts for unauthorized changes.
...
